Workbook

Sheet Sprint Backlog
A1: Sprint ID / Sprint Name | B1: User Story ID | C1: User Story Description | D1: Task ID | E1: Task Description | F1: Assignee | G1: Estimated Effort (Hours) | H1: Actual Effort (Hours) | I1: Status | J1: Start Date | K1: End Date | L1: Remarks
A2: SP-01 / Sprint 1 - Foundation & Authentication | B2: US-01 | C2: As a system owner I need a relational schema so patient, doctor and appointment data is stored reliably | D2: T-101 | E2: Design DDL for users, patients, doctors, departments, rooms, appointments, payments | F2: Rahul (Backend) | G2: 10 | H2: 9 | I2: Done | J2: 2026-06-01 | K2: 2026-06-02 | L2: Includes CHECK constraints for mobile format
A3: SP-01 / Sprint 1 - Foundation & Authentication | B3: US-01 | C3: As a system owner I need a relational schema so patient, doctor and appointment data is stored reliably | D3: T-102 | E3: Add Postgres EXCLUDE constraints for doctor and room overlap | F3: Rahul (Backend) | G3: 6 | H3: 8 | I3: Done | J3: 2026-06-02 | K3: 2026-06-03 | L3: btree_gist extension required; MySQL falls back to service checks
A4: SP-01 / Sprint 1 - Foundation & Authentication | B4: US-01 | C4: As a system owner I need a relational schema so patient, doctor and appointment data is stored reliably | D4: T-103 | E4: Create JPA entities with Hibernate Validator annotations | F4: Sneha (Backend) | G4: 12 | H4: 12 | I4: Done | J4: 2026-06-03 | K4: 2026-06-05 | L4: Lombok builders used to keep entities short
A5: SP-01 / Sprint 1 - Foundation & Authentication | B5: US-02 | C5: As a visitor I want to register as a patient so that I can book appointments | D5: T-104 | E5: Registration API with unique email check | F5: Sneha (Backend) | G5: 8 | H5: 8 | I5: Done | J5: 2026-06-05 | K5: 2026-06-08
A6: SP-01 / Sprint 1 - Foundation & Authentication | B6: US-02 | C6: As a visitor I want to register as a patient so that I can book appointments | D6: T-105 | E6: Registration form with confirm password and strong password rules | F6: Aditya (Frontend) | G6: 10 | H6: 11 | I6: Done | J6: 2026-06-08 | K6: 2026-06-09 | L6: Password rule mirrored on client and server
A7: SP-01 / Sprint 1 - Foundation & Authentication | B7: US-03 | C7: As a registered user I want to log in securely so that only I can see my records | D7: T-106 | E7: JWT issue and validation filter | F7: Rahul (Backend) | G7: 10 | H7: 10 | I7: Done | J7: 2026-06-05 | K7: 2026-06-08
A8: SP-01 / Sprint 1 - Foundation & Authentication | B8: US-03 | C8: As a registered user I want to log in securely so that only I can see my records | D8: T-107 | E8: Spring Security config with role based URL rules | F8: Rahul (Backend) | G8: 8 | H8: 7 | I8: Done | J8: 2026-06-08 | K8: 2026-06-09
A9: SP-01 / Sprint 1 - Foundation & Authentication | B9: US-03 | C9: As a registered user I want to log in securely so that only I can see my records | D9: T-108 | E9: Angular auth service, token interceptor and route guards | F9: Aditya (Frontend) | G9: 10 | H9: 10 | I9: Done | J9: 2026-06-09 | K9: 2026-06-10
A10: SP-01 / Sprint 1 - Foundation & Authentication | B10: US-04 | C10: As a visitor I want to browse doctors and departments before logging in | D10: T-109 | E10: Public doctor and department endpoints with search | F10: Sneha (Backend) | G10: 6 | H10: 6 | I10: Done | J10: 2026-06-09 | K10: 2026-06-10
A11: SP-01 / Sprint 1 - Foundation & Authentication | B11: US-04 | C11: As a visitor I want to browse doctors and departments before logging in | D11: T-110 | E11: Landing page with specialists and departments tables | F11: Priya (Frontend) | G11: 10 | H11: 12 | I11: Done | J11: 2026-06-10 | K11: 2026-06-12 | L11: Department filter added on review feedback
A12: SP-01 / Sprint 1 - Foundation & Authentication | B12: US-05 | C12: As a QA engineer I need seed data so the app is testable from the first run | D12: T-111 | E12: DataSeeder with admin, 3 departments, 4 doctors, 4 rooms | F12: Faiz (QA) | G12: 4 | H12: 4 | I12: Done | J12: 2026-06-11 | K12: 2026-06-12
A13: SP-01 / Sprint 1 - Foundation & Authentication | B13: US-05 | C13: As a QA engineer I need seed data so the app is testable from the first run | D13: T-112 | E13: Smoke test pack for auth and public endpoints | F13: Faiz (QA) | G13: 6 | H13: 6 | I13: Done | J13: 2026-06-11 | K13: 2026-06-12
A14: SP-02 / Sprint 2 - Booking, Collision & Payment | B14: US-06 | C14: As a patient I want to see which slots are free so that I can pick a convenient time | D14: T-201 | E14: Slot generation from doctor availability and slot length | F14: Sneha (Backend) | G14: 10 | H14: 11 | I14: Done | J14: 2026-06-15 | K14: 2026-06-16 | L14: Past slots marked unavailable
A15: SP-02 / Sprint 2 - Booking, Collision & Payment | B15: US-06 | C15: As a patient I want to see which slots are free so that I can pick a convenient time | D15: T-202 | E15: Slot picker UI with availability markers | F15: Priya (Frontend) | G15: 8 | H15: 8 | I15: Done | J15: 2026-06-16 | K15: 2026-06-17
A16: SP-02 / Sprint 2 - Booking, Collision & Payment | B16: US-07 | C16: As a hospital I must never double-book a doctor or a room | D16: T-203 | E16: Collision validation service for doctor overlap | F16: Rahul (Backend) | G16: 10 | H16: 10 | I16: Done | J16: 2026-06-15 | K16: 2026-06-17 | L16: Core acceptance criterion
A17: SP-02 / Sprint 2 - Booking, Collision & Payment | B17: US-07 | C17: As a hospital I must never double-book a doctor or a room | D17: T-204 | E17: Room occupancy validation and free-room endpoint | F17: Rahul (Backend) | G17: 8 | H17: 9 | I17: Done | J17: 2026-06-17 | K17: 2026-06-18
A18: SP-02 / Sprint 2 - Booking, Collision & Payment | B18: US-07 | C18: As a hospital I must never double-book a doctor or a room | D18: T-205 | E18: Concurrency test - two bookings for the same slot | F18: Faiz (QA) | G18: 8 | H18: 10 | I18: Done | J18: 2026-06-18 | K18: 2026-06-19 | L18: Verified DB constraint catches the race
A19: SP-02 / Sprint 2 - Booking, Collision & Payment | B19: US-08 | C19: As a patient I want to request an appointment and track its status | D19: T-206 | E19: Booking API returning PENDING appointment | F19: Sneha (Backend) | G19: 8 | H19: 8 | I19: Done | J19: 2026-06-16 | K19: 2026-06-18
A20: SP-02 / Sprint 2 - Booking, Collision & Payment | B20: US-08 | C20: As a patient I want to request an appointment and track its status | D20: T-207 | E20: Booking page with room preference and reason | F20: Priya (Frontend) | G20: 10 | H20: 10 | I20: Done | J20: 2026-06-18 | K20: 2026-06-19
A21: SP-02 / Sprint 2 - Booking, Collision & Payment | B21: US-08 | C21: As a patient I want to request an appointment and track its status | D21: T-208 | E21: Patient dashboard with appointment table and live status | F21: Aditya (Frontend) | G21: 10 | H21: 10 | I21: Done | J21: 2026-06-19 | K21: 2026-06-22
A22: SP-02 / Sprint 2 - Booking, Collision & Payment | B22: US-09 | C22: As a patient I want to pay the consultation fee and get a receipt | D22: T-209 | E22: PaymentService abstraction and pending payment on booking | F22: Rahul (Backend) | G22: 6 | H22: 6 | I22: Done | J22: 2026-06-22 | K22: 2026-06-23
A23: SP-02 / Sprint 2 - Booking, Collision & Payment | B23: US-09 | C23: As a patient I want to pay the consultation fee and get a receipt | D23: T-210 | E23: Card payment endpoint - Luhn check, store last 4 digits only | F23: Rahul (Backend) | G23: 10 | H23: 12 | I23: Done | J23: 2026-06-23 | K23: 2026-06-24 | L23: PAN and CVV never persisted
A24: SP-02 / Sprint 2 - Booking, Collision & Payment | B24: US-09 | C24: As a patient I want to pay the consultation fee and get a receipt | D24: T-211 | E24: Payment page with masked card input and terms checkbox | F24: Priya (Frontend) | G24: 10 | H24: 10 | I24: Done | J24: 2026-06-24 | K24: 2026-06-25
A25: SP-02 / Sprint 2 - Booking, Collision & Payment | B25: US-09 | C25: As a patient I want to pay the consultation fee and get a receipt | D25: T-212 | E25: Printable receipt view with print stylesheet | F25: Aditya (Frontend) | G25: 8 | H25: 9 | I25: Done | J25: 2026-06-25 | K25: 2026-06-26 | L25: Receipt typography locked against mobile auto-linking
A26: SP-02 / Sprint 2 - Booking, Collision & Payment | B26: US-10 | C26: As a patient I want a refund when I cancel a paid appointment | D26: T-213 | E26: Cancel flow with automatic refund and admin remark | F26: Sneha (Backend) | G26: 8 | H26: 8 | I26: Done | J26: 2026-06-25 | K26: 2026-06-26
A27: SP-03 / Sprint 3 - Admin Console, Search & UI | B27: US-11 | C27: As an admin I want to approve or reject appointment requests | D27: T-301 | E27: Approve and reject endpoints with mandatory remarks | F27: Sneha (Backend) | G27: 8 | H27: 8 | I27: Done | J27: 2026-06-29 | K27: 2026-06-30
A28: SP-03 / Sprint 3 - Admin Console, Search & UI | B28: US-11 | C28: As an admin I want to approve or reject appointment requests | D28: T-302 | E28: Request queue table with inline actions and room assignment | F28: Aditya (Frontend) | G28: 10 | H28: 10 | I28: Done | J28: 2026-06-30 | K28: 2026-07-01
A29: SP-03 / Sprint 3 - Admin Console, Search & UI | B29: US-12 | C29: As an admin I want CRUD screens for doctors, departments, rooms and patients | D29: T-303 | E29: Admin CRUD endpoints and validation rules | F29: Rahul (Backend) | G29: 12 | H29: 12 | I29: Done | J29: 2026-06-29 | K29: 2026-07-01
A30: SP-03 / Sprint 3 - Admin Console, Search & UI | B30: US-12 | C30: As an admin I want CRUD screens for doctors, departments, rooms and patients | D30: T-304 | E30: Six-tab admin dashboard with forms and tables | F30: Aditya (Frontend) | G30: 14 | H30: 15 | I30: Done | J30: 2026-07-01 | K30: 2026-07-03
A31: SP-03 / Sprint 3 - Admin Console, Search & UI | B31: US-12 | C31: As an admin I want CRUD screens for doctors, departments, rooms and patients | D31: T-305 | E31: Doctor years of experience field end to end | F31: Priya (Frontend) | G31: 4 | H31: 4 | I31: Done | J31: 2026-07-03 | K31: 2026-07-03
A32: SP-03 / Sprint 3 - Admin Console, Search & UI | B32: US-13 | C32: As an admin I want to find records quickly and clean up in bulk | D32: T-306 | E32: Search bars - appointment ID/date, doctor ID/specialty, patient ID/date | F32: Priya (Frontend) | G32: 10 | H32: 10 | I32: Done | J32: 2026-07-03 | K32: 2026-07-06
A33: SP-03 / Sprint 3 - Admin Console, Search & UI | B33: US-13 | C33: As an admin I want to find records quickly and clean up in bulk | D33: T-307 | E33: Bulk delete endpoints and multi-select tables | F33: Rahul (Backend) | G33: 8 | H33: 8 | I33: Done | J33: 2026-07-06 | K33: 2026-07-07
A34: SP-03 / Sprint 3 - Admin Console, Search & UI | B34: US-14 | C34: As an admin I want to track whether a patient is admitted or discharged | D34: T-308 | E34: Patient status field with auto-discharge rule | F34: Sneha (Backend) | G34: 8 | H34: 9 | I34: Done | J34: 2026-07-06 | K34: 2026-07-07 | L34: Auto-discharge runs when the patient list loads
A35: SP-03 / Sprint 3 - Admin Console, Search & UI | B35: US-14 | C35: As an admin I want to track whether a patient is admitted or discharged | D35: T-309 | E35: Status column with admit and discharge actions | F35: Priya (Frontend) | G35: 6 | H35: 6 | I35: Done | J35: 2026-07-07 | K35: 2026-07-08
A36: SP-03 / Sprint 3 - Admin Console, Search & UI | B36: US-15 | C36: As a user I want clear feedback for every action | D36: T-310 | E36: Global exception handler and error flattening | F36: Rahul (Backend) | G36: 6 | H36: 6 | I36: Done | J36: 2026-07-01 | K36: 2026-07-02
A37: SP-03 / Sprint 3 - Admin Console, Search & UI | B37: US-15 | C37: As a user I want clear feedback for every action | D37: T-311 | E37: Popup service for success and error dialogs | F37: Aditya (Frontend) | G37: 6 | H37: 6 | I37: Done | J37: 2026-07-02 | K37: 2026-07-03
A38: SP-03 / Sprint 3 - Admin Console, Search & UI | B38: US-16 | C38: As a hospital I want the portal to look professional and print correctly | D38: T-312 | E38: Native CSS theme, logo and navbar with home button | F38: Priya (Frontend) | G38: 10 | H38: 11 | I38: Done | J38: 2026-07-08 | K38: 2026-07-09 | L38: No CSS framework used, per NFR-04
A39: SP-03 / Sprint 3 - Admin Console, Search & UI | B39: US-16 | C39: As a hospital I want the portal to look professional and print correctly | D39: T-313 | E39: Responsive checks and print stylesheet QA | F39: Faiz (QA) | G39: 6 | H39: 6 | I39: Done | J39: 2026-07-09 | K39: 2026-07-10
A40: SP-03 / Sprint 3 - Admin Console, Search & UI | B40: US-17 | C40: As a project team we need release artefacts | D40: T-314 | E40: Regression pass across all roles | F40: Faiz (QA) | G40: 8 | H40: 8 | I40: Done | J40: 2026-07-09 | K40: 2026-07-10
...

Sheet Sprint Summary
A1: Sprint ID | B1: Sprint Name | C1: Start Date | D1: End Date | E1: Working Days | F1: Tasks | G1: Estimated (h) | H1: Actual (h) | I1: Done | J1: Variance (h) | K1: Velocity (h/day)
A2: SP-01 | B2: Sprint 1 - Foundation & Authentication | C2: 2026-06-01 | D2: 2026-06-12 | E2: 10 | F2: =COUNTIFS('Sprint Backlog'!$A$2:$A$41,$A2&" / "&$B2) -> 12 | G2: =SUMIFS('Sprint Backlog'!$G$2:$G$41,'Sprint Backlog'!$A$2:$A$41,$A2&" / "&$B2) -> 100 | H2: =SUMIFS('Sprint Backlog'!$H$2:$H$41,'Sprint Backlog'!$A$2:$A$41,$A2&" / "&$B2) -> 103 | I2: =COUNTIFS('Sprint Backlog'!$A$2:$A$41,$A2&" / "&$B2,'Sprint Backlog'!$I$2:$I$41,"Done") -> 12 | J2: =H2-G2 -> 3 | K2: =IF($E2=0,0,H2/$E2) -> 10.3
A3: SP-02 | B3: Sprint 2 - Booking, Collision & Payment | C3: 2026-06-15 | D3: 2026-06-26 | E3: 10 | F3: =COUNTIFS('Sprint Backlog'!$A$2:$A$41,$A3&" / "&$B3) -> 13 | G3: =SUMIFS('Sprint Backlog'!$G$2:$G$41,'Sprint Backlog'!$A$2:$A$41,$A3&" / "&$B3) -> 114 | H3: =SUMIFS('Sprint Backlog'!$H$2:$H$41,'Sprint Backlog'!$A$2:$A$41,$A3&" / "&$B3) -> 121 | I3: =COUNTIFS('Sprint Backlog'!$A$2:$A$41,$A3&" / "&$B3,'Sprint Backlog'!$I$2:$I$41,"Done") -> 13 | J3: =H3-G3 -> 7 | K3: =IF($E3=0,0,H3/$E3) -> 12.1
A4: SP-03 | B4: Sprint 3 - Admin Console, Search & UI | C4: 2026-06-29 | D4: 2026-07-10 | E4: 10 | F4: =COUNTIFS('Sprint Backlog'!$A$2:$A$41,$A4&" / "&$B4) -> 15 | G4: =SUMIFS('Sprint Backlog'!$G$2:$G$41,'Sprint Backlog'!$A$2:$A$41,$A4&" / "&$B4) -> 124 | H4: =SUMIFS('Sprint Backlog'!$H$2:$H$41,'Sprint Backlog'!$A$2:$A$41,$A4&" / "&$B4) -> 127 | I4: =COUNTIFS('Sprint Backlog'!$A$2:$A$41,$A4&" / "&$B4,'Sprint Backlog'!$I$2:$I$41,"Done") -> 15 | J4: =H4-G4 -> 3 | K4: =IF($E4=0,0,H4/$E4) -> 12.7
B5: TOTAL | F5: =SUM(F2:F4) -> 40 | G5: =SUM(G2:G4) -> 338 | H5: =SUM(H2:H4) -> 351 | I5: =SUM(I2:I4) -> 40 | J5: =H5-G5 -> 13
A7: All figures are formulas over the Sprint Backlog sheet - add a task there and this summary updates itself. Variance = Actual - Estimated (positive means the sprint over-ran its estimate).
